<?xml version="1.0" encoding="UTF-8"?>
<!-- Generated by org.testng.reporters.JUnitXMLReporter -->
<testsuite hostname="PS20190614XSZM" tests="4" failures="2" timestamp="22 Feb 2022 08:55:34 GMT" time="0.015" errors="0">
  <testcase name="test1" time="0.005" classname="ReportTest">
    <failure type="java.lang.AssertionError" message="expected [2] but found [1]">
      <![CDATA[java.lang.AssertionError: expected [2] but found [1]
	at ReportTest.test1(ReportTest.java:8)
... Removed 33 stack frames]]>
    </failure>
  </testcase> <!-- test1 -->
  <testcase name="test2" time="0.0" classname="ReportTest"/>
  <testcase name="test3" time="0.0" classname="ReportTest"/>
  <testcase name="logDemo" time="0.0" classname="ReportTest">
    <failure type="java.lang.RuntimeException" message="这是我自己运行时候的异常">
      <![CDATA[java.lang.RuntimeException: 这是我自己运行时候的异常
	at ReportTest.logDemo(ReportTest.java:24)
... Removed 28 stack frames]]>
    </failure>
  </testcase> <!-- logDemo -->
</testsuite>
